#VRML_SIM V6.0 utf8
WorldInfo {
  info [
    "Demo of a gantry robot playing the Hanoi Towers."
    "The robot moves a stack of colored blocks from one location to another, using the recursive Hanoi Towers algorithm."
    "Author: Yvan Bourquin"
    "Biologically Inspired Robotics Group (BIRG)"
    "Date: May 17, 2013"
  ]
  title "Gantry Robot"
  CFM 0.0001 
  ERP 0.6 
  basicTimeStep 4 
  displayRefresh 8 
  lineScale 0.5
}
Viewpoint {
  orientation 0.0549383 0.986794 0.152379 3.78655 
  position -2.1419 1.79289 -2.26954 
}
Background {
  skyColor [
    0.647059 0.792157 0.937255
  ]
}
DirectionalLight {
  ambientIntensity 2.5 
  direction 0.2 -0.4 0.1 
  intensity 0.9 
  castShadows TRUE 
}
MetricFloor {
}
DEF RAIL1 Solid {
  translation 0.532 0.01 0 
  children [
    DEF RAIL_SHAPE Shape {
      appearance DEF RAIL_APPEARANCE Appearance {
        material Material {
          shininess 0.6 
          specularColor 0.5 0.5 0.5 
        }
      }
      geometry Box {
        size 0.02 0.02 80 
      }
    }
  ]
  boundingObject USE RAIL_SHAPE
  locked TRUE 
}
DEF RAIL2 Solid {
  translation 0.468 0.01 0 
  children [
    USE RAIL_SHAPE
  ]
  boundingObject USE RAIL_SHAPE
  locked TRUE 
}
DEF RAIL3 Solid {
  translation -0.468 0.01 0 
  children [
    USE RAIL_SHAPE
  ]
  boundingObject USE RAIL_SHAPE
  locked TRUE 
}
DEF RAIL4 Solid {
  translation -0.532 0.01 0 
  children [
    USE RAIL_SHAPE
  ]
  boundingObject USE RAIL_SHAPE
  locked TRUE 
}
DEF GANTRY Robot {
  translation 0 0.98 0 
  children [
    DEF PILLARS_GROUP Group {
      children [
        DEF BRIDGE_TRANS Transform {
          translation 0 0.11 0 
          children [
            Shape {
              appearance DEF YELLOW_APPEARANCE Appearance {
                material Material {
                  diffuseColor 1 1 0 
                }
              }
              geometry Box {
                size 2 0.12 0.2 
              }
            }
          ]
        }
        DEF PILLAR1_TRANS Transform {
          translation 0.5 -0.44 -0.4 
          children [
            DEF PILLAR_SHAPE Shape {
              appearance USE YELLOW_APPEARANCE
              geometry Box {
                size 0.1 1 0.1 
              }
            }
          ]
        }
        DEF PILLAR2_TRANS Transform {
          translation -0.5 -0.44 -0.4 
          children [
            USE PILLAR_SHAPE
          ]
        }
        DEF PILLAR3_TRANS Transform {
          translation 0.5 -0.44 0.4 
          children [
            USE PILLAR_SHAPE
          ]
        }
        DEF PILLAR4_TRANS Transform {
          translation -0.5 -0.44 0.4 
          children [
            USE PILLAR_SHAPE
          ]
        }
        DEF TRANSVERSE1 Transform {
          translation -0.5 0.11 0 
          children [
            DEF TRANSVERSE_SHAPE Shape {
              appearance USE YELLOW_APPEARANCE
              geometry Box {
                size 0.1 0.1 0.9 
              }
            }
          ]
        }
        DEF TRANSVERSE2 Transform {
          translation 0.5 0.11 0 
          children [
            USE TRANSVERSE_SHAPE
          ]
        }
      ]
    }
    DEF WHEEL1_HINGE_JOINT HingeJoint {
      device RotationalMotor {
        name "wheel1_motor"
      }
      jointParameters HingeJointParameters {
        axis 1 0 0 
        anchor 0.5 -0.9 -0.4 
      }
      endPoint Solid {
        translation 0.5 -0.9 -0.4 
        rotation 1 0 0 0 
        children [
          DEF WHEEL1_TRANS Transform {
            rotation 0 0 1 1.5708 
            children [
              DEF WHEEL_SHAPE Shape {
                appearance DEF WHEEL_APPEARANCE Appearance {
                  material Material {
                    diffuseColor 0 0 0 
                  }
                }
                geometry Cylinder {
                  height 0.04 
                  radius 0.08 
                }
              }
            ]
          }
        ]
        boundingObject USE WHEEL1_TRANS
        physics DEF WHEEL_PHYSICS Physics {
        }
      }
    }
    DEF WHEEL2_HINGE_JOINT HingeJoint {
      device RotationalMotor {
        name "wheel2_motor"
      }
      jointParameters HingeJointParameters {
        axis 1 0 0 
        anchor -0.5 -0.9 -0.4 
      }
      endPoint Solid {
        translation -0.5 -0.9 -0.4 
        rotation 1 0 0 0 
        children [
          DEF WHEEL2_TRANS Transform {
            rotation 0 0 1 1.5708 
            children [
              USE WHEEL_SHAPE
            ]
          }
        ]
        boundingObject USE WHEEL2_TRANS
        physics USE WHEEL_PHYSICS
      }
    }
    DEF WHEEL3_HINGE_JOINT HingeJoint {
      device RotationalMotor {
        name "wheel3_motor"
      }
      jointParameters HingeJointParameters {
        axis 1 0 0 
        anchor 0.5 -0.9 0.4 
      }
      endPoint Solid {
        translation 0.5 -0.9 0.4 
        rotation 1 0 0 0 
        children [
          DEF WHEEL3_TRANS Transform {
            rotation 0 0 1 1.5708 
            children [
              USE WHEEL_SHAPE
            ]
          }
        ]
        boundingObject USE WHEEL3_TRANS
        physics USE WHEEL_PHYSICS
      }
    }
    DEF WHEEL4_HINGE_JOINT HingeJoint {
      device RotationalMotor {
        name "wheel4_motor"
      }
      jointParameters HingeJointParameters {
        axis 1 0 0 
        anchor -0.5 -0.9 0.4 
      }
      endPoint Solid {
        translation -0.5 -0.9 0.4 
        rotation 1 0 0 0 
        children [
          DEF WHEEL4_TRANS Transform {
            rotation 0 0 1 1.5708 
            children [
              USE WHEEL_SHAPE
            ]
          }
        ]
        boundingObject USE WHEEL4_TRANS
        physics USE WHEEL_PHYSICS
      }
    }
    DEF BRIDGE_SLIDER_JOINT SliderJoint {
      device LinearMotor {
        name "bridge_motor"
        maxVelocity 1 
        minPosition -0.9 
        maxPosition 0.9 
        maxForce 100 
      }
      jointParameters JointParameters {
        axis -1 0 3.67321e-06 
        minStop -0.9 
        maxStop 0.9 
      }
      endPoint Solid {
        rotation 0 1 0 1.5708 
        children [
          DEF TURRET_HINGE_JOINT HingeJoint {
            device RotationalMotor {
              name "turret_motor"
              maxVelocity 3.14 
              maxTorque 100 
            }
            jointParameters HingeJointParameters {
              axis 0 1 0 
              anchor 0 0.11 0 
            }
            endPoint Solid {
              translation 0 0.11 0 
              rotation 0 1 0 1.5708 
              children [
                DEF TURRET_SHAPE Shape {
                  appearance USE WHEEL_APPEARANCE
                  geometry Cylinder {
                    height 0.16 
                    radius 0.08 
                  }
                }
                DEF LIFT_SLIDER_JOINT SliderJoint {
                  device LinearMotor {
                    name "lift_motor"
                    maxVelocity 1 
                    maxPosition 0.73 
                    maxForce 400 
                  }
                  jointParameters JointParameters {
                    axis 0 1 3.67321e-06 
                    maxStop 0.73 
                  }
                  endPoint Solid {
                    translation 0 0.36 0 
                    rotation 1 0 0 1.5708 
                    children [
                      DEF PISTON_GROUP Group {
                        children [
                          Transform {
                            translation 0 0 0.5 
                            children [
                              Shape {
                                appearance USE RAIL_APPEARANCE
                                geometry Box {
                                  size 0.2 0.4 0.04 
                                }
                              }
                            ]
                          }
                          Transform {
                            rotation 1 0 0 1.5708 
                            children [
                              Shape {
                                appearance USE RAIL_APPEARANCE
                                geometry Cylinder {
                                  height 1 
                                  radius 0.05 
                                }
                              }
                            ]
                          }
                        ]
                      }
                      DEF GRIPPER_SLIDER_JOINT1 SliderJoint {
                        device LinearMotor {
                          name "grip_motor1"
                          maxPosition 0.18 
                          maxForce 200 
                        }
                        jointParameters JointParameters {
                          axis 0 -1 3.67321e-06 
                          maxStop 0.18 
                        }
                        endPoint Solid {
                          translation 0 -0.19 0.6 
                          rotation 1 0 0 -1.5708 
                          children [
                            DEF GRIPPER_SHAPE Shape {
                              appearance USE RAIL_APPEARANCE
                              geometry Box {
                                size 0.2 0.16 0.02 
                              }
                            }
                          ]
                          boundingObject USE GRIPPER_SHAPE
                          physics Physics {
                          }
                        }
                      }
                      DEF GRIPPER_SLIDER_JOINT2 SliderJoint {
                        device LinearMotor {
                          name "grip_motor2"
                          maxPosition 0.18 
                          maxForce 200 
                        }
                        jointParameters JointParameters {
                          axis 0 1 3.67321e-06 
                          maxStop 0.18 
                        }
                        endPoint Solid {
                          translation 0 0.19 0.6 
                          rotation 1 0 0 1.5708 
                          children [
                            USE GRIPPER_SHAPE
                          ]
                          boundingObject USE GRIPPER_SHAPE
                          physics Physics {
                          }
                        }
                      }
                    ]
                    boundingObject USE PISTON_GROUP
                    physics Physics {
                    }
                  }
                }
              ]
              boundingObject USE TURRET_SHAPE
              physics Physics {
              }
            }
          }
        ]
        boundingObject Box {
          size 0.01 0.01 0.01 
        }
        physics Physics {
        }
      }
    }
  ]
  boundingObject USE PILLARS_GROUP
  physics Physics {
  }
#  controller "gantry"
  controller "irteusgl"
  controllerArgs "motor_demo.l (main)"
}
DEF BOX_A Solid {
  translation 0.8 0.55 0 
  children [
    DEF BOX_SHAPE Shape {
      appearance Appearance {
        material Material {
          diffuseColor 0 0 1 
        }
        texture ImageTexture {
          url [
            "gantry/A.png"
          ]
        }
      }
      geometry Box {
        size 0.2 0.2 0.2 
      }
    }
  ]
  boundingObject USE BOX_SHAPE
  physics Physics {
  }
}
DEF BOX_B Solid {
  translation 0.8 0.35 0 
  children [
    DEF BOX_SHAPE Shape {
      appearance Appearance {
        material Material {
          diffuseColor 0 1 0 
        }
        texture ImageTexture {
          url [
            "gantry/B.png"
          ]
        }
      }
      geometry Box {
        size 0.2 0.2 0.2 
      }
    }
  ]
  boundingObject USE BOX_SHAPE
  physics Physics {
  }
}
DEF BOX_C Solid {
  translation 0.8 0.15 0 
  children [
    DEF BOX_SHAPE Shape {
      appearance Appearance {
        material Material {
          diffuseColor 1 0 0 
        }
        texture ImageTexture {
          url [
            "gantry/C.png"
          ]
        }
      }
      geometry Box {
        size 0.2 0.2 0.2 
      }
    }
  ]
  boundingObject USE BOX_SHAPE
  physics Physics {
  }
}
DEF PLATFORM_1 Solid {
  translation 0.8 0.02 0 
  children [
    DEF PLATFORM1_SHAPE Shape {
      appearance Appearance {
        material Material {
          diffuseColor 0.498039 0.498039 0.498039 
        }
        texture ImageTexture {
          url [
            "gantry/1.png"
          ]
        }
      }
      geometry Box {
        size 0.4 0.04 0.4 
      }
    }
  ]
  boundingObject USE PLATFORM1_SHAPE
}
DEF PLATFORM_2 Solid {
  translation -0.8 0.02 0.794 
  children [
    DEF PLATFORM2_SHAPE Shape {
      appearance Appearance {
        material Material {
          diffuseColor 0.498039 0.498039 0.498039 
        }
        texture ImageTexture {
          url [
            "gantry/2.png"
          ]
        }
      }
      geometry Box {
        size 0.4 0.04 0.4 
      }
    }
  ]
  boundingObject USE PLATFORM2_SHAPE
}
