#VRML_SIM V6.0 utf8
WorldInfo {
  info [
    "Model for the course: Models of Biological Sensory-Motor Systems"
    "With active and passive (spring & dampers) knee joints and touch sensors."
    "Author: Yvan Bourquin"
    "Copyright (C) 2007 Biologically Inspired Robotics Group (BIRG)"
    "Ecole Polytechnique Federale de Lausanne (EPFL), Switzerland"
  ]
  title "Ghostdog"
  CFM 0.0001 
  ERP 0.6 
  basicTimeStep 4 
  displayRefresh 8 
  lineScale 0.1
  contactProperties [
    ContactProperties {
      material1 "floor"
      forceDependentSlip 0.01 
    }
  ]
}
Viewpoint {
  orientation -0.00148696 0.999007 0.0445305 3.16888 
  position -0.0834002 0.3156 -1.4536 
  follow "ghostdog"
}
Background {
  skyColor [
    0.4 0.7 1
  ]
}
DirectionalLight {
  ambientIntensity 2.2 
  direction 0.2 -0.5 0.3 
  intensity 1.2 
  castShadows TRUE 
}
DEF GHOSTDOG Robot {
  translation 0 0.3 0 
  children [
    DEF BODY_SHAPE Shape {
      appearance DEF BODY_APPEARANCE Appearance {
        material Material {
        }
      }
      geometry Box {
        size 0.3 0.1 0.2 
      }
    }
    DEF NECK0 HingeJoint {
      device RotationalMotor {
        name "neck0"
        maxVelocity 100 
        minPosition -1 
        maxPosition 1 
        maxTorque 100 
      }
      jointParameters HingeJointParameters {
        axis 0 0 1 
        anchor 0.15 0 0 
      }
      endPoint Solid {
        translation 0.15 0 0 
        rotation 0 0 1 2.3562 
        children [
          DEF NECK0_CYL_TRANS Transform {
            rotation 1 0 0 1.5708 
            children [
              DEF NECK0_CYL_SHAPE Shape {
                appearance DEF JOINT_APPEARANCE Appearance {
                  material Material {
                    diffuseColor 1 0.7 0 
                  }
                }
                geometry Cylinder {
                  height 0.04 
                  radius 0.04 
                }
              }
            ]
          }
          DEF NECK0_BOX_TRANS Transform {
            translation 0 -0.05 0 
            children [
              Shape {
                appearance USE BODY_APPEARANCE
                geometry Box {
                  size 0.05 0.1 0.03 
                }
              }
            ]
          }
          DEF NECK1 HingeJoint {
            device RotationalMotor {
              name "neck1"
              maxVelocity 100 
              minPosition -1.5708 
              maxPosition 0.6 
              maxTorque 100 
            }
            jointParameters HingeJointParameters {
              axis 0 0 1 
              anchor 0 -0.1 0 
            }
            endPoint Solid {
              translation 0 -0.1 0 
              rotation 0 0 1 0.7854 
              children [
                DEF NECK1_CYL_TRANS Transform {
                  rotation 1 0 0 1.5708 
                  children [
                    DEF NECK1_CYL_SHAPE Shape {
                      appearance USE JOINT_APPEARANCE
                      geometry Cylinder {
                        height 0.04 
                        radius 0.04 
                      }
                    }
                  ]
                }
                DEF NECK1_BOX_TRANS Transform {
                  translation 0 -0.04 0 
                  children [
                    DEF NECK1_BOX_SHAPE Shape {
                      appearance USE BODY_APPEARANCE
                      geometry Box {
                        size 0.05 0.08 0.03 
                      }
                    }
                  ]
                }
                DEF HEAD HingeJoint {
                  device RotationalMotor {
                    name "head"
                    minPosition -1.5708 
                    maxPosition 1.5708 
                  }
                  jointParameters HingeJointParameters {
                    axis 0 1 0 
                    anchor 0 -0.08 0 
                  }
                  endPoint Solid {
                    translation 0 -0.08 0 
                    children [
                      DEF HEAD_CYL_SHAPE Shape {
                        appearance USE JOINT_APPEARANCE
                        geometry Cylinder {
                          height 0.04 
                          radius 0.04 
                        }
                      }
                      DEF HEAD_BOX_TRANS Transform {
                        translation -0.05 -0.04 0 
                        children [
                          DEF HEAD_SHAPE Shape {
                            appearance USE BODY_APPEARANCE
                            geometry Box {
                              size 0.16 0.1 0.16 
                            }
                          }
                        ]
                      }
                      DEF LEFT_CAM Camera {
                        translation 0 -0.09 -0.09 
                        rotation 0.707107 4.32978e-17 0.707107 3.14159 
                        children [
                          DEF CAM_TRANS Transform {
                            rotation 1 0 0 1.5708 
                            children [
                              Shape {
                                appearance DEF CAM_APPEARANCE Appearance {
                                  material Material {
                                    diffuseColor 0.301961 0.301961 0.301961 
                                  }
                                }
                                geometry Cylinder {
                                  height 0.04 
                                  radius 0.02 
                                }
                              }
                            ]
                          }
                        ]
                        name "left camera"
                        pixelSize 0 
                      }
                      DEF RIGHT_CAM Camera {
                        translation 0 -0.09 0.09 
                        rotation 0.707107 4.32978e-17 0.707107 3.14159 
                        children [
                          USE CAM_TRANS
                        ]
                        name "right camera"
                        pixelSize 0 
                      }
                    ]
                    boundingObject USE HEAD_BOX_TRANS
                    physics Physics {
                      density -1 
                      mass 1.28 
                      centerOfMass [
                        0.0 0.0 0.0
                      ]
                      inertiaMatrix [
                        0.005845 0.008661 0.009045, -0.00256 0.0 0.0
                      ]
                    }
                  }
                }
              ]
              boundingObject USE NECK1_BOX_TRANS
              physics Physics {
                density -1 
                mass 0.06 
                centerOfMass [
                  0.0 0.0 0.0
                ]
                inertiaMatrix [
                  0.000133 0.000017 0.000141, 0.0 0.0 0.0
                ]
              }
            }
          }
        ]
        boundingObject USE NECK0_BOX_TRANS
        physics Physics {
          density -1 
          mass 0.075 
          centerOfMass [
            0.0 0.0 0.0
          ]
          inertiaMatrix [
            0.000256 0.000021 0.000266, 0.0 0.0 0.0
          ]
        }
      }
    }
    DEF HIP0 HingeJoint {
      device RotationalMotor {
        name "hip0"
        maxVelocity 100 
        minPosition -1.5708 
        maxPosition 1.5708 
        maxTorque 100 
      }
      jointParameters HingeJointParameters {
        axis 0 0 1 
        anchor 0.08 0 0.12 
      }
      endPoint Solid {
        translation 0.08 0 0.12 
        rotation 0 0 1 0 
        children [
          DEF HIP_TRANS Transform {
            rotation 1 0 0 1.5708 
            children [
              DEF HIP_SHAPE Shape {
                appearance USE JOINT_APPEARANCE
                geometry Cylinder {
                  height 0.04 
                  radius 0.04 
                }
              }
            ]
          }
          DEF FEMUR_TRANS Transform {
            translation 0 -0.07 0 
            children [
              Shape {
                appearance USE BODY_APPEARANCE
                geometry Box {
                  size 0.05 0.14 0.03 
                }
              }
            ]
          }
          DEF KNEE_TRANS Transform {
            translation 0 -0.14 0 
            rotation 1 0 0 1.5708 
            children [
              DEF KNEE_SHAPE Shape {
                appearance USE JOINT_APPEARANCE
                geometry Cylinder {
                  height 0.04 
                  radius 0.04 
                }
              }
            ]
          }
          DEF KNEE0 HingeJoint {
            device RotationalMotor {
              name "knee0"
              maxVelocity 100 
              minPosition -1.5708 
              maxPosition 1.5708 
              maxTorque 100 
            }
            jointParameters HingeJointParameters {
              axis 0 0 1 
              anchor 0 -0.14 0 
            }
            endPoint Solid {
              translation 0 -0.14 0 
              rotation 0 0 1 0.7 
              children [
                DEF KNEE0SPRING HingeJoint {
                  device RotationalMotor {
                    name "knee0spring"
                  }
                  jointParameters HingeJointParameters {
                    axis 0 0 1 
                    springConstant 20 
                    dampingConstant 0.1 
                  }
                  endPoint Solid {
                    rotation 0 0 1 0 
                    children [
                      DEF TIBIA_TRANS Transform {
                        translation 0 -0.07 0 
                        children [
                          Shape {
                            appearance USE BODY_APPEARANCE
                            geometry Box {
                              size 0.05 0.14 0.03 
                            }
                          }
                        ]
                      }
                      DEF TOUCH0 TouchSensor {
                        translation 0 -0.14 0 
                        rotation 1 0 0 1.5708 
                        children [
                          DEF FOOT_SHAPE Shape {
                            appearance DEF FOOT_APPEARANCE Appearance {
                              material Material {
                                diffuseColor 1 0 0 
                              }
                            }
                            geometry Cylinder {
                              height 0.04 
                              radius 0.04 
                            }
                          }
                        ]
                        name "touch0"
                        boundingObject USE FOOT_SHAPE
                        physics DEF FOOT_PHYSICS Physics {
                          density -1 
                          mass 0.000001 
                          centerOfMass [
                            0.0 0.0 0.0
                          ]
                          inertiaMatrix [
                            0.0000001 0.0000001 0.0000001, 0.0 0.0 0.0
                          ]
                        }
                        type "force"
                        lookupTable [
                          0 0 0, 100 1000 0
                        ]
                      }
                    ]
                    boundingObject DEF DUMMY_BOX Box {
                      size 0.01 0.01 0.01 
                    }
                    physics DEF TIBIA_PHYSICS Physics {
                      density -1 
                      mass 0.201 
                      centerOfMass [
                        0 -0.07 0
                      ]
                      inertiaMatrix [
                        0.000988 0.000003 0.000988, 0.0 0.0 0.0
                      ]
                    }
                  }
                }
              ]
              boundingObject Box {
                size 0.001 0.001 0.001 
              }
              physics USE FOOT_PHYSICS
            }
          }
        ]
        boundingObject USE KNEE_TRANS
        physics DEF FEMUR_PHYSICS Physics {
          density -1 
          mass 0.201062 
          centerOfMass [
            0 -0.07 0
          ]
          inertiaMatrix [
            0.001092 0.000107 0.001146, 0.0 0.0 0.0
          ]
        }
      }
    }
    DEF HIP2 HingeJoint {
      device RotationalMotor {
        name "hip2"
        maxVelocity 100 
        minPosition -1.5708 
        maxPosition 1.5708 
        maxTorque 100 
      }
      jointParameters HingeJointParameters {
        axis 0 0 1 
        anchor 0.08 0 -0.12 
      }
      endPoint Solid {
        translation 0.08 0 -0.12 
        rotation 0 0 1 0 
        children [
          USE HIP_TRANS
          USE FEMUR_TRANS
          USE KNEE_TRANS
          DEF KNEE2 HingeJoint {
            device RotationalMotor {
              name "knee2"
              maxVelocity 100 
              minPosition -1.5708 
              maxPosition 1.5708 
              maxTorque 100 
            }
            jointParameters HingeJointParameters {
              axis 0 0 1 
              anchor 0 -0.14 0 
            }
            endPoint Solid {
              translation 0 -0.14 0 
              rotation 0 0 1 0.7 
              children [
                DEF KNEE2SPRING HingeJoint {
                  device RotationalMotor {
                    name "knee2spring"
                  }
                  jointParameters HingeJointParameters {
                    axis 0 0 1 
                    springConstant 20 
                    dampingConstant 0.1 
                  }
                  endPoint Solid {
                    rotation 0 0 1 0 
                    children [
                      USE TIBIA_TRANS
                      DEF TOUCH2 TouchSensor {
                        translation 0 -0.14 0 
                        rotation 1 0 0 1.5708 
                        children [
                          USE FOOT_SHAPE
                        ]
                        name "touch2"
                        boundingObject USE FOOT_SHAPE
                        physics USE FOOT_PHYSICS
                        type "force"
                        lookupTable [
                          0 0 0, 100 1000 0
                        ]
                      }
                    ]
                    boundingObject USE DUMMY_BOX
                    physics USE TIBIA_PHYSICS
                  }
                }
              ]
              boundingObject Box {
                size 0.001 0.001 0.001 
              }
              physics USE FOOT_PHYSICS
            }
          }
        ]
        boundingObject USE KNEE_TRANS
        physics USE FEMUR_PHYSICS
      }
    }
    DEF PELVIS HingeJoint {
      device RotationalMotor {
        name "spine"
        maxVelocity 100 
        minPosition -0.6 
        maxPosition 0.6 
        maxTorque 100 
      }
      jointParameters HingeJointParameters {
        axis 0 1 0 
        anchor -0.18 0 0 
      }
      endPoint Solid {
        translation -0.18 0 0 
        children [
          DEF PELVIS_CYL_SHAPE Shape {
            appearance USE JOINT_APPEARANCE
            geometry Cylinder {
              height 0.11 
              radius 0.06 
            }
          }
          DEF PELVIS_BOX_SHAPE Transform {
            translation -0.13 0 0 
            children [
              Shape {
                appearance USE BODY_APPEARANCE
                geometry Box {
                  size 0.2 0.1 0.2 
                }
              }
            ]
          }
          DEF HIP1 HingeJoint {
            device RotationalMotor {
              name "hip1"
              maxVelocity 100 
              minPosition -1.5708 
              maxPosition 1.5708 
              maxTorque 100 
            }
            jointParameters HingeJointParameters {
              axis 0 0 1 
              anchor -0.16 0 0.12 
            }
            endPoint Solid {
              translation -0.16 0 0.12 
              rotation 0 0 1 0 
              children [
                USE HIP_TRANS
                USE FEMUR_TRANS
                USE KNEE_TRANS
                DEF KNEE1 HingeJoint {
                  device RotationalMotor {
                    name "knee1"
                    maxVelocity 100 
                    minPosition -1.5708 
                    maxPosition 1.5708 
                    maxTorque 100 
                  }
                  jointParameters HingeJointParameters {
                    axis 0 0 1 
                    anchor 0 -0.14 0 
                  }
                  endPoint Solid {
                    translation 0 -0.14 0 
                    rotation 0 0 1 0.7 
                    children [
                      DEF KNEE1SPRING HingeJoint {
                        device RotationalMotor {
                          name "knee1spring"
                        }
                        jointParameters HingeJointParameters {
                          axis 0 0 1 
                          springConstant 20 
                          dampingConstant 0.1 
                        }
                        endPoint Solid {
                          rotation 0 0 1 0 
                          children [
                            USE TIBIA_TRANS
                            DEF TOUCH1 TouchSensor {
                              translation 0 -0.14 0 
                              rotation 1 0 0 1.5708 
                              children [
                                USE FOOT_SHAPE
                              ]
                              name "touch1"
                              boundingObject USE FOOT_SHAPE
                              physics USE FOOT_PHYSICS
                              type "force"
                              lookupTable [
                                0 0 0, 100 1000 0
                              ]
                            }
                          ]
                          boundingObject USE DUMMY_BOX
                          physics USE TIBIA_PHYSICS
                        }
                      }
                    ]
                    boundingObject Box {
                      size 0.001 0.001 0.001 
                    }
                    physics USE FOOT_PHYSICS
                  }
                }
              ]
              boundingObject USE KNEE_TRANS
              physics USE FEMUR_PHYSICS
            }
          }
          DEF HIP3 HingeJoint {
            device RotationalMotor {
              name "hip3"
              maxVelocity 100 
              minPosition -1.5708 
              maxPosition 1.5708 
              maxTorque 100 
            }
            jointParameters HingeJointParameters {
              axis 0 0 1 
              anchor -0.16 0 -0.12 
            }
            endPoint Solid {
              translation -0.16 0 -0.12 
              rotation 0 0 1 0 
              children [
                USE HIP_TRANS
                USE FEMUR_TRANS
                USE KNEE_TRANS
                DEF KNEE3 HingeJoint {
                  device RotationalMotor {
                    name "knee3"
                    maxVelocity 100 
                    minPosition -1.5708 
                    maxPosition 1.5708 
                    maxTorque 100 
                  }
                  jointParameters HingeJointParameters {
                    axis 0 0 1 
                    anchor 0 -0.14 0 
                  }
                  endPoint Solid {
                    translation 0 -0.14 0 
                    rotation 0 0 1 0.7 
                    children [
                      DEF KNEE3SPRING HingeJoint {
                        device RotationalMotor {
                          name "knee3spring"
                        }
                        jointParameters HingeJointParameters {
                          axis 0 0 1 
                          springConstant 20 
                          dampingConstant 0.1 
                        }
                        endPoint Solid {
                          rotation 0 0 1 0 
                          children [
                            USE TIBIA_TRANS
                            DEF TOUCH3 TouchSensor {
                              translation 0 -0.14 0 
                              rotation 1 0 0 1.5708 
                              children [
                                USE FOOT_SHAPE
                              ]
                              name "touch3"
                              boundingObject USE FOOT_SHAPE
                              physics USE FOOT_PHYSICS
                              type "force"
                              lookupTable [
                                0 0 0, 100 1000 0
                              ]
                            }
                          ]
                          boundingObject USE DUMMY_BOX
                          physics USE TIBIA_PHYSICS
                        }
                      }
                    ]
                    boundingObject Box {
                      size 0.001 0.001 0.001 
                    }
                    physics USE FOOT_PHYSICS
                  }
                }
              ]
              boundingObject USE KNEE_TRANS
              physics USE FEMUR_PHYSICS
            }
          }
        ]
        boundingObject USE PELVIS_BOX_SHAPE
        physics Physics {
          density -1 
          mass 4.0 
          centerOfMass [
            -0.13 0 0
          ]
          inertiaMatrix [
            0.016667 0.026667 0.016667, 0.0 0.0 0.0
          ]
        }
      }
    }
  ]
  name "ghostdog"
  boundingObject USE BODY_SHAPE
  physics Physics {
    density 700 
  }
#  controller "ghostdog"
  controller "irteusgl"
  controllerArgs "motor_demo.l (main)"
}
MetricFloor {
  contactMaterial "floor"
}
