#VRML_SIM V6.0 utf8
WorldInfo {
  info [
    "This example shows a Shrimp III robot (BlueBotics SA)."
    "The robot's mechanical structure passively adapts to the uneven terrain."
    "If you wish you can drive the robot using the keyboard (follow the instructions in Webots Console)."
    "Author: Simon Blanchoud & Luc Guyot (Cyberbotics Ltd)"
    "Date: 17 MAY 2013"
  ]
  title "Shrimp III"
  basicTimeStep 16
}
Viewpoint {
  orientation -0.239013 0.955834 0.171038 1.15025
  position 0.84321 0.406357 4.92234
  follow "Shrimp"
}
Background {
  skyColor [
    0.109804 0.376471 0.54902
  ]
}
DirectionalLight {
  ambientIntensity 2.36
  direction -1.42 -1.21 0.4
  intensity 1.32
  castShadows TRUE
}
DEF GROUND Solid {
  children [
    Shape {
      appearance Appearance {
        material Material {
        }
        texture ImageTexture {
          url [
            "textures/lightwood.png"
          ]
        }
        textureTransform TextureTransform {
          scale 20 20
        }
      }
      geometry DEF GROUND_SHAPE Plane {
        size 20 20
      }
    }
  ]
  boundingObject USE GROUND_SHAPE
  locked TRUE
}
DEF STAIRS Solid {
  translation 0 0 -4.5
  children [
    DEF STAIRS Group {
      children [
        Transform {
          translation 0 0.05 0
          children [
            Shape {
              appearance DEF OBJECTS_APPEARANCE Appearance {
                material Material {
                  diffuseColor 0.5 0.5 0.5
                  shininess 0.8
                  specularColor 0.4 0.4 0.4
                }
              }
              geometry Box {
                size 3 0.1 5
              }
            }
          ]
        }
        Transform {
          translation 0 0.16 0
          children [
            Shape {
              appearance USE OBJECTS_APPEARANCE
              geometry Box {
                size 3 0.12 3.5
              }
            }
          ]
        }
        Transform {
          translation 0 0.295 0
          children [
            Shape {
              appearance USE OBJECTS_APPEARANCE
              geometry Box {
                size 3 0.15 2
              }
            }
          ]
        }
        Transform {
          translation 0 0.09 -3.9
          children [
            Shape {
              appearance USE OBJECTS_APPEARANCE
              geometry Box {
                size 3 0.18 1
              }
            }
          ]
        }
      ]
    }
  ]
  boundingObject USE STAIRS
}
DEF RAMP Solid {
  translation 5 0 0
  children [
    DEF RAMPE Group {
      children [
        Transform {
          translation 0 1 0.001
          rotation 0 0 1 0.5236
          children [
            Shape {
              appearance USE OBJECTS_APPEARANCE
              geometry Box {
                size 2 0.1 2
              }
            }
          ]
        }
        Transform {
          translation -1.7 0.25 0
          rotation 0 0 1 0.3
          children [
            Shape {
              appearance USE OBJECTS_APPEARANCE
              geometry Box {
                size 2 0.1 2
              }
            }
          ]
        }
        Transform {
          translation 1.51 1.49 0
          children [
            Shape {
              appearance USE OBJECTS_APPEARANCE
              geometry Box {
                size 1.33 0.1 2
              }
            }
          ]
        }
        Transform {
          translation 3.1 0.7 0.001
          rotation 0 0 1 -0.7
          children [
            Shape {
              appearance USE OBJECTS_APPEARANCE
              geometry Box {
                size 2.5 0.1 2
              }
            }
          ]
        }
      ]
    }
  ]
  boundingObject USE RAMPE
}
DEF CAPS Solid {
  translation -2 -0.1 0
  rotation 1 0 0 1.5708
  children [
    DEF BUMPS Group {
      children [
        Transform {
          children [
            Shape {
              appearance USE OBJECTS_APPEARANCE
              geometry Capsule {
                radius 0.3
              }
            }
          ]
        }
        Transform {
          translation -0.4 0 0
          children [
            Shape {
              appearance USE OBJECTS_APPEARANCE
              geometry Capsule {
                radius 0.2
              }
            }
          ]
        }
        Transform {
          translation -1.3 0 0
          children [
            Shape {
              appearance USE OBJECTS_APPEARANCE
              geometry Capsule {
                radius 0.336
              }
            }
          ]
        }
        Transform {
          translation -2.2 0 0.05
          children [
            Shape {
              appearance USE OBJECTS_APPEARANCE
              geometry Capsule {
                radius 0.3
              }
            }
          ]
        }
      ]
    }
  ]
  boundingObject USE BUMPS
}
DEF SPHERES Solid {
  translation 0 -0.05 3.5
  children [
    DEF BALLS Group {
      children [
        Transform {
          translation -0.2 -0.06 0
          children [
            Shape {
              appearance USE OBJECTS_APPEARANCE
              geometry Sphere {
                radius 0.15
              }
            }
          ]
        }
        Transform {
          translation 0.35 -0.03 -0.05
          children [
            Shape {
              appearance USE OBJECTS_APPEARANCE
              geometry Sphere {
                radius 0.15
              }
            }
          ]
        }
        Transform {
          translation -0.2 -0.015 -0.4
          children [
            Shape {
              appearance USE OBJECTS_APPEARANCE
              geometry Sphere {
                radius 0.15
              }
            }
          ]
        }
        Transform {
          translation 0.1 0 -0.6
          children [
            Shape {
              appearance USE OBJECTS_APPEARANCE
              geometry Sphere {
                radius 0.15
              }
            }
          ]
        }
        Transform {
          translation 0 0.015 -0.9
          children [
            Shape {
              appearance USE OBJECTS_APPEARANCE
              geometry Sphere {
                radius 0.15
              }
            }
          ]
        }
        Transform {
          translation 0.5 0.02 -0.55
          children [
            Shape {
              appearance USE OBJECTS_APPEARANCE
              geometry Sphere {
                radius 0.15
              }
            }
          ]
        }
        Transform {
          translation 0 0.005 0
          children [
            Shape {
              appearance USE OBJECTS_APPEARANCE
              geometry Sphere {
                radius 0.15
              }
            }
          ]
        }
        Transform {
          translation -0.5 0 -1
          children [
            Shape {
              appearance USE OBJECTS_APPEARANCE
              geometry Sphere {
                radius 0.15
              }
            }
          ]
        }
        Transform {
          translation -0.6 0.03 -0.15
          children [
            Shape {
              appearance USE OBJECTS_APPEARANCE
              geometry Sphere {
                radius 0.15
              }
            }
          ]
        }
        Transform {
          translation 0.4 0 -1.3
          children [
            Shape {
              appearance USE OBJECTS_APPEARANCE
              geometry Sphere {
                radius 0.15
              }
            }
          ]
        }
        Transform {
          translation -0.15 0.04 -1.35
          children [
            Shape {
              appearance USE OBJECTS_APPEARANCE
              geometry Sphere {
                radius 0.15
              }
            }
          ]
        }
      ]
    }
  ]
  boundingObject USE BALLS
}
DEF SHRIMP Robot {
  translation 0.02 0 4.5
  children [
    Group {
      children [
        Transform {
          translation 0 0.159 0
          children [
            DEF BASE Shape {
              appearance DEF BLUE Appearance {
                material Material {
                  diffuseColor 0.109804 0.380392 0.54902
                  shininess 0.6
                  specularColor 0.498039 0.631373 0.713725
                }
              }
              geometry IndexedFaceSet {
                coord Coordinate {
                  point [
                    0.135 0 -0.015
                    0.125 0 -0.025
                    0.125 0 -0.09
                    0.113 0 -0.102
                    0.009 0 -0.102
                    0.009 0 -0.039
                    -0.009 0 -0.039
                    -0.009 0 -0.102
                    -0.113 0 -0.102
                    -0.125 0 -0.09
                    -0.125 0 -0.025
                    -0.135 0 -0.015
                    -0.135 0 0.015
                    -0.125 0 0.025
                    -0.125 0 0.09
                    -0.01 0 0.165
                    0.01 0 0.165
                    0.125 0 0.09
                    0.125 0 0.025
                    0.135 0 0.015
                    0.135 0 -0.015
                    0.135 0.002 -0.015
                    0.125 0.002 -0.025
                    0.125 0.002 -0.09
                    0.113 0.002 -0.102
                    0.009 0.002 -0.102
                    0.009 0.002 -0.039
                    -0.009 0.002 -0.039
                    -0.009 0.002 -0.102
                    -0.113 0.002 -0.102
                    -0.125 0.002 -0.09
                    -0.125 0.002 -0.025
                    -0.135 0.002 -0.015
                    -0.135 0.002 0.015
                    -0.125 0.002 0.025
                    -0.125 0.002 0.09
                    -0.01 0.002 0.165
                    0.01 0.002 0.165
                    0.125 0.002 0.09
                    0.125 0.002 0.025
                    0.135 0.002 0.015
                    0.135 0.002 -0.015
                  ]
                }
                coordIndex [
                  20 19 18 17 16 15 14 13 12 11
                  10 9 8 7 6 5 4 3 2 1
                  0 -1 21 22 23 24 25 26 27 28
                  29 30 31 32 33 34 35 36 37 38
                  39 40 41 -1 0 1 22 21 -1 1
                  2 23 22 -1 2 3 24 23 -1 3
                  4 25 24 -1 4 5 26 25 -1 5
                  6 27 26 -1 6 7 28 27 -1 7
                  8 29 28 -1 8 9 30 29 -1 9
                  10 31 30 -1 10 11 32 31 -1 11
                  12 33 32 -1 12 13 34 33 -1 13
                  14 35 34 -1 14 15 36 35 -1 15
                  16 37 36 -1 16 17 38 37 -1 17
                  18 39 38 -1 18 19 40 39 -1 19
                  20 41 40 -1
                ]
                creaseAngle 0.3
              }
            }
          ]
        }
        Transform {
          translation 0 0.226 0
          children [
            USE BASE
          ]
        }
        Transform {
          translation -0.131 0.193 0
          children [
            DEF LATERAL_SUPPORT Shape {
              appearance USE BLUE
              geometry Box {
                size 0.008 0.068 0.03
              }
            }
          ]
        }
        Transform {
          translation 0.131 0.193 0
          children [
            USE LATERAL_SUPPORT
          ]
        }
        Transform {
          translation -0.013 0.193 -0.062
          children [
            USE LATERAL_SUPPORT
          ]
        }
        Transform {
          translation 0.013 0.193 -0.062
          children [
            USE LATERAL_SUPPORT
          ]
        }
        Transform {
          translation 0 0.193 0.161
          children [
            Shape {
              appearance USE BLUE
              geometry Box {
                size 0.02 0.068 0.008
              }
            }
          ]
        }
        Transform {
          translation 0 0.1455 -0.034
          children [
            Shape {
              appearance USE BLUE
              geometry Box {
                size 0.25 0.027 0.058
              }
            }
          ]
        }
        Transform {
          translation -0.011 0.173 0.1745
          children [
            DEF FRONT_WHEEL_LATERAL_SUPPORT Shape {
              appearance USE BLUE
              geometry Box {
                size 0.002 0.01 0.035
              }
            }
          ]
        }
        Transform {
          translation 0.011 0.173 0.1745
          children [
            USE FRONT_WHEEL_LATERAL_SUPPORT
          ]
        }
        Transform {
          translation 0 0.1755 0.186
          rotation 1 0 0 -0.478
          children [
            Shape {
              appearance USE BLUE
              geometry Box {
                size 0.0201 0.102 0.015
              }
            }
          ]
        }
        DEF ROTATIONAL_MOTOR Group {
          children [
            Transform {
              translation 0 0.138 0.234
              rotation 0 0 1 0
              children [
                Shape {
                  appearance USE BLUE
                  geometry Box {
                    size 0.02 0.01 0.047
                  }
                }
              ]
            }
            Transform {
              translation -0.011 0.153 0.23
              rotation 0 0 1 0
              children [
                DEF MOTOR_SUPPORT Shape {
                  appearance USE BLUE
                  geometry Box {
                    size 0.002 0.04 0.02
                  }
                }
              ]
            }
            Transform {
              translation 0.011 0.153 0.23
              rotation 0 0 1 0
              children [
                USE MOTOR_SUPPORT
              ]
            }
            Transform {
              translation 0 0.178 0.236
              rotation 0 0 1 0
              children [
                DEF MOTOR Shape {
                  appearance DEF BLACK Appearance {
                    material Material {
                      diffuseColor 0.3 0.3 0.3
                    }
                  }
                  geometry Box {
                    size 0.02 0.037 0.04
                  }
                }
              ]
            }
          ]
        }
        Transform {
          translation 0.14 0.2195 0
          rotation 0 0 1 1.57
          children [
            DEF BOGIE_AXE Shape {
              appearance USE BLACK
              geometry Cylinder {
                subdivision 24
                height 0.038
                radius 0.005
              }
            }
          ]
        }
        Transform {
          translation 0.14 0.1695 0
          rotation 0 0 1 1.57
          children [
            USE BOGIE_AXE
          ]
        }
        Transform {
          translation -0.14 0.2195 0
          rotation 0 0 1 1.57
          children [
            USE BOGIE_AXE
          ]
        }
        Transform {
          translation -0.14 0.1695 0
          rotation 0 0 1 1.57
          children [
            USE BOGIE_AXE
          ]
        }
        Transform {
          translation 0 0.2195 -0.053
          rotation 0 0 1 1.57
          children [
            USE BOGIE_AXE
          ]
        }
        Transform {
          translation 0 0.1695 -0.072
          rotation 0 0 1 1.57
          children [
            USE BOGIE_AXE
          ]
        }
      ]
    }
    DEF BACK_WHEEL_HINGE HingeJoint {
      jointParameters HingeJointParameters {
        axis 0 1 0
        anchor 0 0.138 0.252
      }
      device RotationalMotor {
        name "back_wheel_rotation"
        minPosition -1.57
        maxPosition 1.57
      }
      endPoint DEF BACK_WHEEL Solid {
        translation 0 0.138 0.252
        children [
          DEF ROTATIONAL_SUPPORT Group {
            children [
              Transform {
                translation -0.013 -0.009 0
                rotation 0 0 1 0
                children [
                  Shape {
                    appearance USE BLUE
                    geometry Box {
                      size 0.039 0.008 0.01
                    }
                  }
                ]
              }
              Transform {
                translation -0.0285 -0.0425 0
                rotation 0 0 1 0
                children [
                  Shape {
                    appearance USE BLUE
                    geometry Box {
                      size 0.008 0.059 0.01
                    }
                  }
                ]
              }
              Transform {
                translation -0.02 -0.08 0
                rotation 0 0 1 1.57
                children [
                  DEF WHEEL_AXE Shape {
                    appearance USE BLUE
                    geometry Cylinder {
                      subdivision 24
                      height 0.04
                      radius 0.0125
                    }
                  }
                ]
              }
            ]
          }
          DEF BACK_TIRE_HINGE HingeJoint {
            jointParameters HingeJointParameters {
              axis 1 0 0
              anchor 0 -0.08 0
            }
            device RotationalMotor {
              name "wheel_motor05"
              maxTorque 0.754
            }
            endPoint DEF BACK_TIRE Solid {
              translation 0 -0.08 0
              rotation 1 0 0 0
              children [
                DEF WHEEL Group {
                  children [
                    Transform {
                      rotation 0 0 1 1.57
                      children [
                        Shape {
                          appearance USE BLACK
                          geometry Cylinder {
                            subdivision 24
                            height 0.041
                            radius 0.058
                          }
                        }
                      ]
                    }
                    Transform {
                      translation 0.02 0 0
                      rotation 0 0 1 -1.57
                      children [
                        Shape {
                          appearance USE BLUE
                          geometry IndexedFaceSet {
                            coord Coordinate {
                              point [
                                0.007 0.013 -0.002
                                0.047 0 -0.012
                                0.035 0 -0.034
                                0.006 0.013 -0.005
                                0.007 0.013 0.002
                                0.047 0 0.013
                                0.006 0.013 0.005
                                0.035 0 0.034
                                0.002 0.013 0.007
                                0.013 0 0.047
                                -0.001 0.013 0.007
                                -0.012 0 0.047
                                -0.005 0.013 0.005
                                -0.034 0 0.034
                                -0.007 0.013 0.002
                                -0.046 0 0.013
                                -0.046 0 -0.012
                                -0.005 0.013 -0.005
                                -0.034 0 -0.034
                                -0.012 0 -0.047
                                0.013 0 -0.047
                                0 0 0
                                -0.007 0.013 -0.002
                                0.002 0.013 -0.007
                                -0.001 0.013 -0.007
                              ]
                            }
                            coordIndex [
                              1 0 4 -1 4 5 1 -1 5 4
                              6 -1 6 7 5 -1 7 6 8 -1
                              8 9 7 -1 9 8 10 -1 10 11
                              9 -1 11 10 12 -1 12 13 11 -1
                              2 1 21 -1 1 5 21 -1 5 7
                              21 -1 7 9 21 -1 9 11 21 -1
                              11 13 21 -1 13 15 21 -1 15 16
                              21 -1 16 18 21 -1 18 19 21 -1
                              19 20 21 -1 2 21 20 -1 0 1
                              2 -1 0 2 3 -1 2 20 3 -1
                              3 20 23 -1 19 23 20 -1 19 24
                              23 -1 18 24 19 -1 17 24 18 -1
                              16 17 18 -1 16 22 17 -1 15 22
                              16 -1 14 22 15 -1 13 14 15 -1
                              12 14 13 -1 3 23 12 -1 12 23
                              14 -1 14 23 24 -1 14 24 22 -1
                              17 22 24 -1 3 12 10 -1 0 3
                              10 -1 0 10 8 -1 0 8 4 -1
                              4 8 6 -1
                            ]
                            creaseAngle 0.3
                          }
                        }
                      ]
                    }
                  ]
                }
              ]
              boundingObject DEF BOUNDING_WHEEL Transform {
                translation 0.004 0 0
                rotation 0 0 1 1.57
                children [
                  Shape {
                    geometry Cylinder {
                      subdivision 24
                      height 0.05
                      radius 0.058
                    }
                  }
                ]
              }
              physics DEF PHYSICS_WHEEL Physics {
                density -1
                mass 0.222
              }
            }
          }
        ]
        boundingObject DEF BOUNDING_ROTATIONAL_SUPPORT Group {
          children [
            Transform {
              translation -0.013 -0.0425 0
              rotation 0 0 1 0
              children [
                Shape {
                  geometry Box {
                    size 0.039 0.075 0.01
                  }
                }
              ]
            }
            Transform {
              translation -0.02 -0.08 0
              rotation 0 0 1 1.57
              children [
                DEF BOUNDING_WHEEL_AXE Shape {
                  geometry Cylinder {
                    subdivision 24
                    bottom FALSE
                    height 0.04
                    radius 0.0125
                  }
                }
              ]
            }
          ]
        }
        physics DEF PHYSICS_ROTATIONAL_SUPPORT Physics {
          density -1
          mass 0.178
          centerOfMass [
            -0.015 -0.06 0
          ]
          inertiaMatrix [
            0.000117613 2.89259e-05 0.000139178
            -1.08718e-05 0 0
          ]
        }
      }
    }
    DEF UPPER_RIGHT_BOGIE_HINGE HingeJoint {
      jointParameters HingeJointParameters {
        anchor 0.1465 0.2195 0
        minStop -1.35566
        maxStop 1.35566
      }
      endPoint DEF UPPER_RIGHT_BOGIE Solid {
        translation 0.1465 0.2195 0
        rotation 1 0 0 0
        children [
          Transform {
            children [
              DEF BOGIE_HORIZONTAL Shape {
                appearance USE BLUE
                geometry DEF BOUNDING_BOGIE_HORIZONTAL Box {
                  size 0.015 0.015 0.183
                }
              }
            ]
          }
          DEF BACK_RIGHT_BOGIE_HINGE HingeJoint {
            jointParameters HingeJointParameters {
              anchor 0 0 0.089
            }
            endPoint DEF BACK_RIGHT_BOGIE Solid {
              translation 0 -0.2195 0.089
              rotation 1 0 0 0
              children [
                Transform {
                  translation 0 0.147 0
                  children [
                    DEF BOGIE_VERTICAL Shape {
                      appearance USE BLUE
                      geometry DEF BOUNDING_BOGIE_VERTICAL Box {
                        size 0.02 0.16 0.015
                      }
                    }
                  ]
                }
                Transform {
                  translation 0.0165 0.058 0
                  rotation 0 0 1 1.57
                  children [
                    USE WHEEL_AXE
                  ]
                }
                DEF BACK_RIGHT_TIRE_HINGE HingeJoint {
                  jointParameters HingeJointParameters {
                    axis 1 0 0
                    anchor 0.0355 0.058 0
                  }
                  device RotationalMotor {
                    name "wheel_motor04"
                    maxTorque 0.754
                  }
                  endPoint DEF BACK_RIGHT_TIRE_SOLID Solid {
                    translation 0.0355 0.058 0
                    rotation 1 0 0 0
                    children [
                      USE WHEEL
                    ]
                    boundingObject USE BOUNDING_WHEEL
                    physics USE PHYSICS_WHEEL
                  }
                }
              ]
              name "back_right_bogie"
              boundingObject DEF BOUNDING_BOGIE_VERTICAL_AXE Group {
                children [
                  Transform {
                    translation 0 0.147 0
                    children [
                      USE BOUNDING_BOGIE_VERTICAL
                    ]
                  }
                  Transform {
                    translation 0.0165 0.058 0
                    rotation 0 0 1 1.57
                    children [
                      USE BOUNDING_WHEEL_AXE
                    ]
                  }
                ]
              }
              physics DEF PHYSICS_BOGIE_VERTICAL Physics {
                density -1
                mass 0.23263
                centerOfMass [
                  0 0.09 0
                ]
                inertiaMatrix [
                  0.000966127 3.86276e-05 0.000993287
                  3.56632e-05 0 0
                ]
              }
            }
          }
          DEF FRONT_RIGHT_BOGIE_HINGE HingeJoint {
            jointParameters HingeJointParameters {
              anchor 0 0 -0.089
            }
            endPoint DEF FRONT_RIGHT_BOGIE Solid {
              translation 0 -0.2195 -0.089
              rotation 1 0 0 0
              children [
                Transform {
                  translation 0 0.147 0
                  children [
                    USE BOGIE_VERTICAL
                  ]
                }
                Transform {
                  translation 0.0165 0.058 0
                  rotation 0 0 1 1.57
                  children [
                    USE WHEEL_AXE
                  ]
                }
                DEF FRONT_RIGHT_TIRE_HINGE HingeJoint {
                  jointParameters HingeJointParameters {
                    axis 1 0 0
                    anchor 0.0355 0.058 0
                  }
                  device RotationalMotor {
                    name "wheel_motor02"
                    maxTorque 0.754
                  }
                  endPoint DEF FRONT_RIGHT_TIRE Solid {
                    translation 0.0355 0.058 0
                    rotation 1 0 0 0
                    children [
                      USE WHEEL
                    ]
                    boundingObject USE BOUNDING_WHEEL
                    physics USE PHYSICS_WHEEL
                  }
                }
              ]
              name "front_right_bogie"
              boundingObject USE BOUNDING_BOGIE_VERTICAL_AXE
              physics USE PHYSICS_BOGIE_VERTICAL
            }
          }
        ]
        boundingObject USE BOUNDING_BOGIE_HORIZONTAL
        physics DEF PHYSICS_BOGIE_HORIZONTAL Physics {
          density -1
          mass 0.05737
        }
      }
    }
    DEF LOWER_RIGHT_BOGIE_HINGE HingeJoint {
      jointParameters HingeJointParameters {
        minStop -1.35566
        maxStop 1.35566
        anchor 0.1465 0.1695 0
      }
      endPoint DEF LOWER_RIGHT_BOGIE Solid {
        translation 0.1465 0.1695 0
        rotation 1 0 0 0
        children [
          Transform {
            children [
              USE BOGIE_HORIZONTAL
            ]
          }
          DEF BACK_RIGHT_BOGIE_HINGE HingeJoint {
            jointParameters HingeJointParameters {
              anchor 0 0 0.089
            }
            endPoint SolidReference {
              solidName "back_right_bogie"
            }
          }
          DEF FRONT_RIGHT_BOGIE_HINGE HingeJoint {
            jointParameters HingeJointParameters {
              anchor 0 0 -0.089
            }
            endPoint SolidReference {
              solidName "front_right_bogie"
            }
          }
        ]
        boundingObject USE BOUNDING_BOGIE_HORIZONTAL
        physics USE PHYSICS_BOGIE_HORIZONTAL
      }
    }
    DEF UPPER_LEFT_BOGIE_HINGE HingeJoint {
      jointParameters HingeJointParameters {
        minStop -1.35566
        maxStop 1.35566
        anchor -0.1465 0.2195 0
      }
      endPoint DEF UPPER_LEFT_BOGIE Solid {
        translation -0.1465 0.2195 0
        rotation 1 0 0 0
        children [
          Transform {
            children [
              DEF BOGIE_HORIZONTAL Shape {
                appearance USE BLUE
                geometry USE BOUNDING_BOGIE_HORIZONTAL
              }
            ]
          }
          DEF BACK_LEFT_BOGIE_HINGE HingeJoint {
            jointParameters HingeJointParameters {
              anchor 0 0 0.089
            }
            endPoint DEF BACK_LEFT_BOGIE Solid {
              translation 0 -0.2195 0.089
              rotation 0 1 0 3.1415
              children [
                Transform {
                  translation 0 0.147 0
                  children [
                    DEF BOGIE_VERTICAL Shape {
                      appearance USE BLUE
                      geometry USE BOUNDING_BOGIE_VERTICAL
                    }
                  ]
                }
                Transform {
                  translation 0.0165 0.058 0
                  rotation 0 0 1 1.57
                  children [
                    USE WHEEL_AXE
                  ]
                }
                DEF BACK_LEFT_TIRE_HINGE HingeJoint {
                  jointParameters HingeJointParameters {
                    axis 1 0 0
                    anchor 0.0355 0.058 0
                  }
                  device RotationalMotor {
                    name "wheel_motor03"
                    maxTorque 0.754
                  }
                  endPoint DEF BACK_LEFT_TIRE Solid {
                    translation 0.0355 0.058 0
                    rotation 1 0 0 0
                    children [
                      USE WHEEL
                    ]
                    boundingObject USE BOUNDING_WHEEL
                    physics USE PHYSICS_WHEEL
                  }
                }
              ]
              name "back_left_bogie"
              boundingObject USE BOUNDING_BOGIE_VERTICAL_AXE
              physics USE PHYSICS_BOGIE_VERTICAL
            }
          }
          DEF FRONT_LEFT_BOGIE_HINGE HingeJoint {
            jointParameters HingeJointParameters {
              anchor 0 0 -0.089
            }
            endPoint DEF FRONT_LEFT_BOGIE Solid {
              translation 0 -0.2195 -0.089
              rotation 0 1 0 3.1415
              children [
                Transform {
                  translation 0 0.147 0
                  children [
                    USE BOGIE_VERTICAL
                  ]
                }
                Transform {
                  translation 0.0165 0.058 0
                  rotation 0 0 1 1.57
                  children [
                    USE WHEEL_AXE
                  ]
                }
                DEF FRONT_LEFT_TIRE_HINGE HingeJoint {
                  jointParameters HingeJointParameters {
                    axis 1 0 0
                    anchor 0.0355 0.058 0
                  }
                  device RotationalMotor {
                    name "wheel_motor01"
                    maxTorque 0.754
                  }
                  endPoint DEF FRONT_LEFT_TIRE Solid {
                    translation 0.0355 0.058 0
                    rotation 1 0 0 0
                    children [
                      USE WHEEL
                    ]
                    boundingObject USE BOUNDING_WHEEL
                    physics USE PHYSICS_WHEEL
                  }
                }
              ]
              name "front_left_bogie"
              boundingObject USE BOUNDING_BOGIE_VERTICAL_AXE
              physics USE PHYSICS_BOGIE_VERTICAL
            }
          }
        ]
        boundingObject USE BOUNDING_BOGIE_HORIZONTAL
        physics USE PHYSICS_BOGIE_HORIZONTAL
      }
    }
    DEF LOWER_LEFT_BOGIE_HINGE HingeJoint {
      jointParameters HingeJointParameters {
        minStop -1.35566
        maxStop 1.35566
        anchor -0.1465 0.1695 0
      }
      endPoint DEF LOWER_LEFT_BOGIE Solid {
        translation -0.1465 0.1695 0
        rotation 1 0 0 0
        children [
          Transform {
            children [
              USE BOGIE_HORIZONTAL
            ]
          }
          DEF BACK_LEFT_BOGIE_HINGE HingeJoint {
            jointParameters HingeJointParameters {
              anchor 0 0 0.089
            }
            endPoint SolidReference {
              solidName "back_left_bogie"
            }
          }
          DEF FRONT_LEFT_BOGIE_HINGE HingeJoint {
            jointParameters HingeJointParameters {
              anchor  0 0 -0.089
            }
            endPoint SolidReference {
              solidName "front_left_bogie"
            }
          }
        ]
        boundingObject USE BOUNDING_BOGIE_HORIZONTAL
        physics USE PHYSICS_BOGIE_HORIZONTAL
      }
    }
    DEF UPPER_FORK_HINGE HingeJoint {
      jointParameters HingeJointParameters {
        anchor 0 0.2195 -0.053
        minStop -1.93
        maxStop 1.32
      }
      endPoint DEF UPPER_FORK Solid {
        translation 0 0.2445 -0.102
        rotation 1 0 0 0.4712
        children [
          Transform {
            translation 0 0 0.0025
            children [
              Shape {
                appearance USE BLUE
                geometry Box {
                  size 0.015 0.015 0.115
                }
              }
            ]
          }
          DEF FRONT_FORK_HINGE HingeJoint {
            jointParameters HingeJointParameters {
              anchor 0 -0.000225406 -0.0535313
            }
            endPoint DEF FRONT_FORK Solid {
              translation 0 -0.171613 -0.102237
              rotation 1 0 0 -0.4712
              children [
                Transform {
                  translation 0 0.0613 0.0813
                  rotation 1 0 0 -1.04845
                  children [
                    Shape {
                      appearance USE BLUE
                      geometry Box {
                        size 0.02 0.015 0.175
                      }
                    }
                    DEF LOGO Transform {
                      translation 0 0.0085 0.035
                      rotation 1 0 0 0
                      children [
                        Shape {
                          appearance Appearance {
                            material Material {
                              specularColor 0.9 0.9 0.9
                            }
                            texture ImageTexture {
                              url [
                                "textures/bluebotics_logo.png"
                              ]
                            }
                          }
                          geometry IndexedFaceSet {
                            coord Coordinate {
                              point [
                                0.009 0 -0.05
                                0.009 0 0.05
                                -0.009 0 0.05
                                -0.009 0 -0.05
                              ]
                            }
                            texCoord TextureCoordinate {
                              point [
                                0 1
                                0 0
                                1 0
                                1 1
                              ]
                            }
                            coordIndex [
                              0 3 2 1 -1
                            ]
                            texCoordIndex [
                              0 1 2 3 -1
                            ]
                          }
                        }
                      ]
                    }
                  ]
                }
                Transform {
                  translation 0 -0.138 0.251
                  rotation 0 1 0 3.1415
                  children [
                    USE ROTATIONAL_MOTOR
                  ]
                }
                DEF FRONT_WHEEL_HINGE HingeJoint {
                  jointParameters HingeJointParameters {
                    axis 0 1 0
                  }
                  device RotationalMotor {
                    name "front_wheel_rotation"
                    minPosition -1.57
                    maxPosition 1.57
                  }
                  endPoint DEF FRONT_WHEEL Solid {
                    children [
                      USE ROTATIONAL_SUPPORT
                      DEF FRONT_TIRE_HINGE HingeJoint {
                        jointParameters HingeJointParameters {
                          axis 1 0 0
                          anchor 0 -0.08 0
                        }
                        device RotationalMotor {
                          name "wheel_motor00"
                          maxTorque 0.754
                        }
                        endPoint DEF FRONT_TIRE Solid {
                          translation 0 -0.08 0
                          rotation 1 0 0 0
                          children [
                            USE WHEEL
                          ]
                          boundingObject USE BOUNDING_WHEEL
                          physics USE PHYSICS_WHEEL
                        }
                      }
                    ]
                    boundingObject USE BOUNDING_ROTATIONAL_SUPPORT
                    physics USE PHYSICS_ROTATIONAL_SUPPORT
                  }
                }
              ]
              name "front_fork"
              boundingObject Group {
                children [
                  Transform {
                    translation 0 0.0613 0.0813
                    rotation 1 0 0 -1.04845
                    children [
                      Shape {
                        geometry Box {
                          size 0.02 0.015 0.175
                        }
                      }
                    ]
                  }
                  Transform {
                    translation 0 0.027 0.015
                    rotation 0 0 1 0
                    children [
                      Shape {
                        geometry Box {
                          size 0.024 0.062 0.04
                        }
                      }
                    ]
                  }
                ]
              }
              physics Physics {
                density -1
                mass 0.1159
                centerOfMass [
                  0 0.03 0.05
                ]
                inertiaMatrix [
                  0.000350003 0.000176901 0.000182635
                  0 0 -0.00011918
                ]
              }
            }
          }
          DEF UPPER_SPRINGS_HINGE HingeJoint {
            jointParameters HingeJointParameters {
              anchor 0 -2.40438e-05 -0.0150266
            }
            endPoint DEF UPPER_SPRINGS Solid {
              translation 0 -0.0196439 -0.0191718
              rotation 1 0 0 0.20808
              children [
                DEF RIGHT_SPRING Transform {
                  translation -0.015 0 0
                  rotation 1 0 0 0
                  children [
                    DEF SPRING Shape {
                      appearance USE BLACK
                      geometry Cylinder {
                        subdivision 24
                        height 0.04
                        radius 0.0075
                      }
                    }
                  ]
                }
                DEF LEFT_SPRING Transform {
                  translation 0.015 0 0
                  rotation 1 0 0 0
                  children [
                    USE SPRING
                  ]
                }
              ]
              name "upper_springs"
              boundingObject DEF BOUNDING_SPRINGS Group {
                children [
                  Transform {
                    translation 0.015 0 0
                    children [
                      USE SPRING
                    ]
                  }
                  Transform {
                    translation -0.015 0 0
                    children [
                      USE SPRING
                    ]
                  }
                ]
              }
              physics DEF PHYSICS_SPRINGS Physics {
                density -1
                mass 0.02
              }
            }
          }
        ]
        boundingObject Transform {
          children [
            Shape {
              geometry Box {
                size 0.015 0.015 0.12
              }
            }
          ]
        }
        physics Physics {
          density -1
          mass 0.03806
          centerOfMass [
            0 -0.015 0
          ]
          inertiaMatrix [
            5.49491e-05 4.63856e-05 9.99075e-06
            0 0 0
          ]
        }
      }
    }
    DEF LOWER_FORK_HINGE HingeJoint {
      jointParameters HingeJointParameters {
        anchor 0 0.1695 -0.072
      }
      endPoint DEF LOWER_FORK Solid {
        translation 0 0.18875 -0.128825
        rotation 1 0 0 0.3506
        children [
          Transform {
            translation 0 0 0.0025
            children [
              Shape {
                appearance USE BLUE
                geometry Box {
                  size 0.015 0.015 0.125
                }
              }
            ]
          }
          DEF FRONT_FORK_HINGE HingeJoint {
            jointParameters HingeJointParameters {
              anchor 0 -0.00223624 -0.0618707
            }
            endPoint SolidReference {
              solidName "front_fork"
            }
          }
          DEF LOWER_SPRINGS_HINGE HingeJoint {
            jointParameters HingeJointParameters {
              anchor 0 0.001436 -0.0299928
            }
            endPoint DEF LOWER_SPRINGS Solid {
              translation 0 0.0204146 -0.0235173
              rotation 1 0 0 0.32868
              children [
                USE RIGHT_SPRING
                USE LEFT_SPRING
                DEF UPPER_SPRINGS_SLIDER SliderJoint {
                  jointParameters JointParameters {
                    axis 0 0.778025 -0.628233
                    springConstant 4905
                  }
                  endPoint SolidReference {
                    solidName "upper_springs"
                  }
                }
              ]
              name "lower_springs"
              boundingObject USE BOUNDING_SPRINGS
              physics USE PHYSICS_SPRINGS
            }
          }
        ]
        name "lower_fork"
        boundingObject Box {
          size 0.015 0.015 0.13
        }
        physics Physics {
          density -1
          mass 0.04492
        }
      }
    }
  ]
  name "Shrimp"
  boundingObject DEF BOUNDING_BODY Group {
    children [
      Transform {
        translation 0 0.193 -0.005
        children [
          Shape {
            geometry Box {
              size 0.25 0.068 0.192
            }
          }
        ]
      }
      Transform {
        translation 0.0523 0.193 0.109
        rotation 0 1 0 0.578
        children [
          DEF BOUNDING_BASE Shape {
            geometry Box {
              size 0.14 0.068 0.05
            }
          }
        ]
      }
      Transform {
        translation -0.0523 0.193 0.109
        rotation 0 1 0 -0.578
        children [
          USE BOUNDING_BASE
        ]
      }
      Transform {
        translation 0 0.1455 -0.034
        children [
          Shape {
            geometry Box {
              size 0.25 0.027 0.058
            }
          }
        ]
      }
      Transform {
        translation 0 0.193 0.1
        children [
          Shape {
            geometry Box {
              size 0.06 0.068 0.03
            }
          }
        ]
      }
      Transform {
        translation 0 0.1755 0.186
        rotation 1 0 0 -0.478
        children [
          Shape {
            geometry Box {
              size 0.02 0.102 0.015
            }
          }
        ]
      }
      Transform {
        translation 0 0.165 0.236
        rotation 0 0 1 0
        children [
          Shape {
            geometry Box {
              size 0.024 0.062 0.04
            }
          }
        ]
      }
    ]
  }
  physics Physics {
    density -1
    mass 3.322
    centerOfMass [
      0 0.13785 0.03604
    ]
    inertiaMatrix [
      0.0288494 0.0342201 0.0261036
      7.00127e-20 1.83044e-20 0.00196405
    ]
  }
#  controller "shrimp"
  controller "irteusgl"
  controllerArgs "motor_demo.l (main)"
}
