#VRML_SIM V6.0 utf8
WorldInfo {
  title "KUKA youBot"
  info [
    "Simulation of the KUKA youBot robot."
    "This model includes an accurate and fast simulation of the Meccanum wheels."
    "The robot can be equiped with various sensors (including the Microsoft Kinect) and configured with zero, one or two arms."
    "Author: Fabien Rohrer <fabien.rohrer@cyberbotics.com>"
    "Date: 24 May 2011"
  ]
  physics "fast_wheels"
  basicTimeStep 16
}
Viewpoint {
  orientation 0.0511013 0.982835 0.177269 3.71169
  position -0.668662 0.789395 -1.09725
  follow "robot"
}
Background {
  skyColor [
    0.580392 0.705882 0.772549
  ]
}
DirectionalLight {
  ambientIntensity 4
  direction -0.22 -1 0.56
  intensity 1.3
  castShadows TRUE
}
DirectionalLight {
  direction 0.65 -1 0.93
  intensity 0.4
}
DEF GROUND Solid {
  children [
    DEF GROUND_SHAPE Shape {
      appearance Appearance {
        texture ImageTexture {
          url [
            "textures/parquetry.png"
          ]
        }
        textureTransform TextureTransform {
          scale 200 200
        }
      }
      geometry Plane {
        size 100 100
      }
    }
  ]
  boundingObject USE GROUND_SHAPE
}
WoodBox {
  translation 0.605448 0.2 -0.00121984
  boxSize 0.6 0.4 0.6
}
KukaBox {
  translation 0.472629 0.41876 -0.00710068
}
Robot {
  translation 0 0.102838 0
  rotation 1 0 0 -1.5708
  children [
    BodyMesh {
    }
    DEF ARM Solid {
      translation 0.156 0 0
      children [
        Arm0Mesh {
        }
        HingeJoint {
          device RotationalMotor {
            name "arm1"
            maxVelocity 1.5708
            minPosition -2.9496
            maxPosition 2.9496
            maxTorque 9.5
          }
          jointParameters HingeJointParameters {
            axis 0 0 1
            anchor 0 0 0.077
          }
          endPoint Solid {
            translation 0 0 0.077
            rotation 0 0 1 0
            children [
              Arm1Mesh {
              }
              HingeJoint {
                device RotationalMotor {
                  name "arm2"
                  maxVelocity 1.5708
                  minPosition -1.13446
                  maxPosition 1.5708
                  maxTorque 9.5
                }
                jointParameters HingeJointParameters {
                  axis 0 -1 0
                  anchor 0.033 0 0.07
                }
                endPoint Solid {
                  translation 0.033 0 0.07
                  rotation 0 -1 0 0
                  children [
                    Arm2Mesh {
                    }
                    HingeJoint {
                      device RotationalMotor {
                        name "arm3"
                        maxVelocity 1.5708
                        minPosition -2.63545
                        maxPosition 2.54818
                        maxTorque 6
                      }
                      jointParameters HingeJointParameters {
                        axis 0 -1 0
                        anchor 0 0 0.155
                      }
                      endPoint Solid {
                        translation 0 0 0.155
                        rotation 0 -1 0 0
                        children [
                          Arm3Mesh {
                          }
                          HingeJoint {
                            device RotationalMotor {
                              name "arm4"
                              maxVelocity 1.5708
                              minPosition -1.78024
                              maxPosition 1.78024
                              maxTorque 2
                            }
                            jointParameters HingeJointParameters {
                              axis 0 -1 0
                              anchor 0 0 0.135
                            }
                            endPoint Solid {
                              translation 0 0 0.135
                              rotation 0 -1 0 0
                              children [
                                Arm4Mesh {
                                }
                                HingeJoint {
                                  device RotationalMotor {
                                    name "arm5"
                                    maxVelocity 1.5708
                                    minPosition -2.92343
                                    maxPosition 2.92343
                                    maxTorque 1
                                  }
                                  jointParameters HingeJointParameters {
                                    axis 0 0 1
                                    anchor 0 0 0.081
                                  }
                                  endPoint Solid {
                                    translation 0 0 0.081
                                    rotation 0 0 1 0
                                    children [
                                      Arm5Mesh {
                                      }
                                      SliderJoint {
                                        jointParameters JointParameters {
                                          axis 0 -1 0
                                        }
                                        device LinearMotor {
                                          name "finger1"
                                          maxPosition 0.025
                                          maxForce 100
                                        }
                                        endPoint Solid {
                                          translation 0 0 0.09
                                          rotation 1 0 0 4.71239
                                          children [
                                            FingerMesh {
                                            }
                                          ]
                                          boundingObject DEF FINGER_BO Group {
                                            children [
                                              Transform {
                                                translation 0 -0.031 0.015
                                                children [
                                                  Box {
                                                    size 0.014 0.032 0.009
                                                  }
                                                ]
                                              }
                                              Transform {
                                                translation 0 -0.007 0.01
                                                children [
                                                  Box {
                                                    size 0.014 0.015 0.019
                                                  }
                                                ]
                                              }
                                            ]
                                          }
                                          physics DEF FINGER_PH Physics {
                                            density -1
                                            mass 0.03
                                            centerOfMass [
                                              0 -0.02 0.01
                                            ]
                                            inertiaMatrix [
                                              6.84034e-06 1.41763e-06 6.40271e-06, 0 0 8.29319e-07
                                            ]
                                          }
                                        }
                                      }
                                      SliderJoint {
                                        jointParameters JointParameters {
                                          axis 0 1 0
                                        }
                                        device LinearMotor {
                                          name "finger2"
                                          maxPosition 0.025
                                          maxForce 100
                                        }
                                        endPoint Solid {
                                          translation 0 0 0.09
                                          rotation 0 -0.707107 0.707107 3.14159
                                          children [
                                            FingerMesh {
                                            }
                                          ]
                                          boundingObject USE FINGER_BO
                                          physics USE FINGER_PH
                                        }
                                      }
                                    ]
                                    boundingObject Transform {
                                      translation 0 0 0.045
                                      children [
                                        Box {
                                          size 0.025 0.07 0.09
                                        }
                                      ]
                                    }
                                    physics Physics {
                                      density -1
                                      mass 0.251
                                      centerOfMass [
                                        0 0 0.045
                                      ]
                                      inertiaMatrix [
                                        0.000271917 0.000182498 0.000115565, 0 0 0
                                      ]
                                    }
                                  }
                                }
                              ]
                              boundingObject Group {
                                children [
                                  Transform {
                                    translation 0 0 0.056
                                    children [
                                      Box {
                                        size 0.05 0.095 0.05
                                      }
                                    ]
                                  }
                                  Transform {
                                    translation 0 -0.024 0.003
                                    children [
                                      Cylinder {
                                        height 0.047
                                        radius 0.027
                                      }
                                    ]
                                  }
                                ]
                              }
                              physics Physics {
                                density -1
                                mass 0.877
                                centerOfMass [
                                  0 0 0.026
                                ]
                                inertiaMatrix [
                                  0.00152517 0.00103897 0.000837339, 0 0 -0.00015098
                                ]
                              }
                            }
                          }
                        ]
                        boundingObject Transform {
                          translation 0 0.0225 0.065
                          children [
                            Box {
                              size 0.06 0.045 0.19
                            }
                          ]
                        }
                        physics Physics {
                          density -1
                          mass 0.934
                          centerOfMass [
                            0 0.0225 0.065
                          ]
                          inertiaMatrix [
                            0.0029674 0.00308998 0.000437812, 0 0 -5.99276e-20
                          ]
                        }
                      }
                    }
                  ]
                  boundingObject Transform {
                    translation 0 -0.03 0.078
                    children [
                      Box {
                        size 0.07 0.06 0.21
                      }
                    ]
                  }
                  physics Physics {
                    density -1
                    mass 1.155
                    centerOfMass [
                      0 -0.03 0.078
                    ]
                    inertiaMatrix [
                      0.00459113 0.00471625 0.000818125, 0 0 1.56701e-20
                    ]
                  }
                }
              }
            ]
            boundingObject Transform {
              translation 0.032 0.023 0.07
              children [
                Cylinder {
                  height 0.046
                  radius 0.036
                }
              ]
            }
            physics Physics {
              density -1
              mass 2.412
              centerOfMass [
                0.015 0.01 0.05
              ]
              inertiaMatrix [
                0.00257923 0.00322484 0.0023115, -0.000533052 -0.00082008 -0.00062712
              ]
            }
          }
        }
      ]
      boundingObject Transform {
        translation 0 0 0.04
        rotation 1 0 0 1.5708
        children [
          Cylinder {
            height 0.08
            radius 0.078
          }
        ]
      }
      physics Physics {
        density -1
        mass 0.845
        centerOfMass [
          0 0 0.04
        ]
        inertiaMatrix [
          0.00173591 0.00173591 0.00257049, 0 0 -3.06558e-09
        ]
      }
    }
    DEF WHEEL1 FastInteriorWheel {
      translation 0.228 -0.158 -0.055
      anchor 0.228 -0.158 -0.055
      name "wheel1"
    }
    DEF WHEEL2 FastExteriorWheel {
      translation 0.228 0.158 -0.055
      anchor 0.228 0.158 -0.055
      name "wheel2"
    }
    DEF WHEEL3 FastExteriorWheel {
      translation -0.228 -0.158 -0.055
      anchor -0.228 -0.158 -0.055
      name "wheel3"
    }
    DEF WHEEL4 FastInteriorWheel {
      translation -0.228 0.158 -0.055
      anchor -0.228 0.158 -0.055
      name "wheel4"
    }
    DEF PLATE Solid {
      translation -0.155 0 0
      children [
        PlateMesh {
        }
      ]
      boundingObject Group {
        children [
          Transform {
            translation 0.008 0 0.045
            children [
              Box {
                size 0.25 0.17 0.007
              }
            ]
          }
          Transform {
            translation -0.015 0.112 0.045
            rotation 0 0 1 -0.13
            children [
              Box {
                size 0.17 0.08 0.007
              }
            ]
          }
          Transform {
            translation -0.015 -0.112 0.045
            rotation 0 0 1 0.13
            children [
              Box {
                size 0.17 0.08 0.007
              }
            ]
          }
          Transform {
            translation 0.076 0.084 0.045
            rotation 0 0 1 0.81
            children [
              Box {
                size 0.08 0.08 0.007
              }
            ]
          }
          Transform {
            translation 0.076 -0.084 0.045
            rotation 0 0 1 -0.81
            children [
              Box {
                size 0.08 0.08 0.007
              }
            ]
          }
        ]
      }
      physics Physics {
        density -1
        mass 0.5
      }
    }
  ]
  description "KUKA youBot"
  boundingObject Group {
    children [
      Transform {
        translation 0 0 -0.045
        children [
          Box {
            size 0.34 0.34 0.09
          }
        ]
      }
      Transform {
        translation 0 0 -0.045
        children [
          Box {
            size 0.56 0.23 0.09
          }
        ]
      }
    ]
  }
  physics Physics {
    density -1
    mass 22
    centerOfMass [
      0 0 -0.045
    ]
    inertiaMatrix [
      0.166204 0.418086 0.55459, 0 0 0
    ]
  }
#  controller "youbot"
  controller "irteusgl"
  controllerArgs "motor_demo.l (main)"
}
